[2024-12-15T22:16:08.731+0000] {taskinstance.py:1159} INFO - Dependencies all met for dep_context=non-requeueable deps ti=<TaskInstance: covid_data_pipeline.store_data manual__2024-12-15T22:05:57.227850+00:00 [queued]>
[2024-12-15T22:16:08.746+0000] {taskinstance.py:1159} INFO - Dependencies all met for dep_context=requeueable deps ti=<TaskInstance: covid_data_pipeline.store_data manual__2024-12-15T22:05:57.227850+00:00 [queued]>
[2024-12-15T22:16:08.747+0000] {taskinstance.py:1361} INFO - Starting attempt 2 of 2
[2024-12-15T22:16:08.768+0000] {taskinstance.py:1382} INFO - Executing <Task(PythonOperator): store_data> on 2024-12-15 22:05:57.227850+00:00
[2024-12-15T22:16:08.777+0000] {standard_task_runner.py:57} INFO - Started process 451 to run task
[2024-12-15T22:16:08.783+0000] {standard_task_runner.py:84} INFO - Running: ['***', 'tasks', 'run', 'covid_data_pipeline', 'store_data', 'manual__2024-12-15T22:05:57.227850+00:00', '--job-id', '33', '--raw', '--subdir', 'DAGS_FOLDER/covid_pipeline_dag.py', '--cfg-path', '/tmp/tmpl2hls4ha']
[2024-12-15T22:16:08.788+0000] {standard_task_runner.py:85} INFO - Job 33: Subtask store_data
[2024-12-15T22:16:08.901+0000] {task_command.py:416} INFO - Running <TaskInstance: covid_data_pipeline.store_data manual__2024-12-15T22:05:57.227850+00:00 [running]> on host efb61c2ab0bb
[2024-12-15T22:16:09.072+0000] {taskinstance.py:1662} INFO - Exporting env vars: AIRFLOW_CTX_DAG_EMAIL='ctw2012105@@gmail.com' AIRFLOW_CTX_DAG_OWNER='***' AIRFLOW_CTX_DAG_ID='covid_data_pipeline' AIRFLOW_CTX_TASK_ID='store_data' AIRFLOW_CTX_EXECUTION_DATE='2024-12-15T22:05:57.227850+00:00' AIRFLOW_CTX_TRY_NUMBER='2' AIRFLOW_CTX_DAG_RUN_ID='manual__2024-12-15T22:05:57.227850+00:00'
[2024-12-15T22:16:09.129+0000] {data_warehouse.py:56} INFO - Saving data to warehouse table: covid_daily_stats
[2024-12-15T22:16:09.134+0000] {data_warehouse.py:80} ERROR - Error saving to warehouse: 'str' object has no attribute 'strftime'
[2024-12-15T22:16:09.136+0000] {taskinstance.py:1937} ERROR - Task failed with exception
Traceback (most recent call last):
  File "/home/airflow/.local/lib/python3.8/site-packages/airflow/operators/python.py", line 192, in execute
    return_value = self.execute_callable()
  File "/home/airflow/.local/lib/python3.8/site-packages/airflow/operators/python.py", line 209, in execute_callable
    return self.python_callable(*self.op_args, **self.op_kwargs)
  File "/opt/airflow/dags/covid_pipeline_dag.py", line 145, in store_data
    warehouse.save_to_warehouse(df)
  File "/opt/airflow/src/storage/data_warehouse.py", line 59, in save_to_warehouse
    current_date = df['extraction_date'].iloc[0].strftime('%Y-%m-%d')
AttributeError: 'str' object has no attribute 'strftime'
[2024-12-15T22:16:09.166+0000] {taskinstance.py:1400} INFO - Marking task as FAILED. dag_id=covid_data_pipeline, task_id=store_data, execution_date=20241215T220557, start_date=20241215T221608, end_date=20241215T221609
[2024-12-15T22:16:09.210+0000] {logging_mixin.py:154} WARNING - /home/***/.local/lib/python3.8/site-packages/***/utils/email.py:154 RemovedInAirflow3Warning: Fetching SMTP credentials from configuration variables will be deprecated in a future release. Please set credentials using a connection instead.
[2024-12-15T22:16:09.211+0000] {configuration.py:1050} WARNING - section/key [smtp/smtp_user] not found in config
[2024-12-15T22:16:09.215+0000] {email.py:270} INFO - Email alerting: attempt 1
[2024-12-15T22:16:09.238+0000] {configuration.py:1050} WARNING - section/key [smtp/smtp_user] not found in config
[2024-12-15T22:16:09.239+0000] {email.py:270} INFO - Email alerting: attempt 1
[2024-12-15T22:16:09.240+0000] {taskinstance.py:2007} ERROR - Failed to send email to: ['ctw2012105@@gmail.com']
Traceback (most recent call last):
  File "/home/airflow/.local/lib/python3.8/site-packages/airflow/models/taskinstance.py", line 1518, in _run_raw_task
    self._execute_task_with_callbacks(context, test_mode, session=session)
  File "/home/airflow/.local/lib/python3.8/site-packages/airflow/models/taskinstance.py", line 1681, in _execute_task_with_callbacks
    result = self._execute_task(context, task_orig)
  File "/home/airflow/.local/lib/python3.8/site-packages/airflow/models/taskinstance.py", line 1744, in _execute_task
    result = execute_callable(context=context, **execute_callable_kwargs)
  File "/home/airflow/.local/lib/python3.8/site-packages/airflow/operators/python.py", line 192, in execute
    return_value = self.execute_callable()
  File "/home/airflow/.local/lib/python3.8/site-packages/airflow/operators/python.py", line 209, in execute_callable
    return self.python_callable(*self.op_args, **self.op_kwargs)
  File "/opt/airflow/dags/covid_pipeline_dag.py", line 145, in store_data
    warehouse.save_to_warehouse(df)
  File "/opt/airflow/src/storage/data_warehouse.py", line 59, in save_to_warehouse
    current_date = df['extraction_date'].iloc[0].strftime('%Y-%m-%d')
AttributeError: 'str' object has no attribute 'strftime'

During handling of the above exception, another exception occurred:

Traceback (most recent call last):
  File "/home/airflow/.local/lib/python3.8/site-packages/airflow/models/taskinstance.py", line 2420, in email_alert
    send_email(task.email, subject, html_content)
  File "/home/airflow/.local/lib/python3.8/site-packages/airflow/utils/email.py", line 80, in send_email
    return backend(
  File "/home/airflow/.local/lib/python3.8/site-packages/airflow/utils/email.py", line 154, in send_email_smtp
    send_mime_email(e_from=mail_from, e_to=recipients, mime_msg=msg, conn_id=conn_id, dryrun=dryrun)
  File "/home/airflow/.local/lib/python3.8/site-packages/airflow/utils/email.py", line 272, in send_mime_email
    smtp_conn = _get_smtp_connection(smtp_host, smtp_port, smtp_timeout, smtp_ssl)
  File "/home/airflow/.local/lib/python3.8/site-packages/airflow/utils/email.py", line 316, in _get_smtp_connection
    return smtplib.SMTP(host=host, port=port, timeout=timeout)
  File "/usr/local/lib/python3.8/smtplib.py", line 255, in __init__
    (code, msg) = self.connect(host, port)
  File "/usr/local/lib/python3.8/smtplib.py", line 339, in connect
    self.sock = self._get_socket(host, port, self.timeout)
  File "/usr/local/lib/python3.8/smtplib.py", line 310, in _get_socket
    return socket.create_connection((host, port), timeout,
  File "/usr/local/lib/python3.8/socket.py", line 808, in create_connection
    raise err
  File "/usr/local/lib/python3.8/socket.py", line 796, in create_connection
    sock.connect(sa)
ConnectionRefusedError: [Errno 111] Connection refused

During handling of the above exception, another exception occurred:

Traceback (most recent call last):
  File "/home/airflow/.local/lib/python3.8/site-packages/airflow/models/taskinstance.py", line 2005, in handle_failure
    self.email_alert(error, task)
  File "/home/airflow/.local/lib/python3.8/site-packages/airflow/models/taskinstance.py", line 2422, in email_alert
    send_email(task.email, subject, html_content_err)
  File "/home/airflow/.local/lib/python3.8/site-packages/airflow/utils/email.py", line 80, in send_email
    return backend(
  File "/home/airflow/.local/lib/python3.8/site-packages/airflow/utils/email.py", line 154, in send_email_smtp
    send_mime_email(e_from=mail_from, e_to=recipients, mime_msg=msg, conn_id=conn_id, dryrun=dryrun)
  File "/home/airflow/.local/lib/python3.8/site-packages/airflow/utils/email.py", line 272, in send_mime_email
    smtp_conn = _get_smtp_connection(smtp_host, smtp_port, smtp_timeout, smtp_ssl)
  File "/home/airflow/.local/lib/python3.8/site-packages/airflow/utils/email.py", line 316, in _get_smtp_connection
    return smtplib.SMTP(host=host, port=port, timeout=timeout)
  File "/usr/local/lib/python3.8/smtplib.py", line 255, in __init__
    (code, msg) = self.connect(host, port)
  File "/usr/local/lib/python3.8/smtplib.py", line 339, in connect
    self.sock = self._get_socket(host, port, self.timeout)
  File "/usr/local/lib/python3.8/smtplib.py", line 310, in _get_socket
    return socket.create_connection((host, port), timeout,
  File "/usr/local/lib/python3.8/socket.py", line 808, in create_connection
    raise err
  File "/usr/local/lib/python3.8/socket.py", line 796, in create_connection
    sock.connect(sa)
ConnectionRefusedError: [Errno 111] Connection refused
[2024-12-15T22:16:09.273+0000] {standard_task_runner.py:104} ERROR - Failed to execute job 33 for task store_data ('str' object has no attribute 'strftime'; 451)
[2024-12-15T22:16:09.292+0000] {local_task_job_runner.py:228} INFO - Task exited with return code 1
[2024-12-15T22:16:09.331+0000] {taskinstance.py:2778} INFO - 0 downstream tasks scheduled from follow-on schedule check
